2017-11-01 16:52:18,745 ERROR django.request Internal Server Error: /admin/
Traceback (most recent call last):
  File "/home/ubuntu/artemis/env/local/lib/python2.7/site-packages/django/core/handlers/exception.py", line 41, in inner
    response = get_response(request)
  File "/home/ubuntu/artemis/env/local/lib/python2.7/site-packages/django/core/handlers/base.py", line 172, in _get_response
    resolver_match = resolver.resolve(request.path_info)
  File "/home/ubuntu/artemis/env/local/lib/python2.7/site-packages/django/urls/resolvers.py", line 362, in resolve
    for pattern in self.url_patterns:
  File "/home/ubuntu/artemis/env/local/lib/python2.7/site-packages/django/utils/functional.py", line 35, in __get__
    res = instance.__dict__[self.name] = self.func(instance)
  File "/home/ubuntu/artemis/env/local/lib/python2.7/site-packages/django/urls/resolvers.py", line 405, in url_patterns
    patterns = getattr(self.urlconf_module, "urlpatterns", self.urlconf_module)
  File "/home/ubuntu/artemis/env/local/lib/python2.7/site-packages/django/utils/functional.py", line 35, in __get__
    res = instance.__dict__[self.name] = self.func(instance)
  File "/home/ubuntu/artemis/env/local/lib/python2.7/site-packages/django/urls/resolvers.py", line 398, in urlconf_module
    return import_module(self.urlconf_name)
  File "/usr/lib/python2.7/importlib/__init__.py", line 37, in import_module
    __import__(name)
  File "/home/ubuntu/artemis/artemis/artemis/urls.py", line 25, in <module>
    urlpatterns += static(settings.STATIC_URL, document_root=settings.STATIC_ROOT)
NameError: name 'static' is not defined
2017-11-01 18:27:07,682 WARNING django.request Not Found: /
2017-11-01 18:27:07,888 WARNING django.request Not Found: /favicon.ico
2017-11-01 20:59:25,786 WARNING django.request Not Found: /
2017-11-01 21:15:08,856 ERROR django.request Internal Server Error: /
Traceback (most recent call last):
  File "/home/ubuntu/artemis/env/local/lib/python2.7/site-packages/django/core/handlers/exception.py", line 41, in inner
    response = get_response(request)
  File "/home/ubuntu/artemis/env/local/lib/python2.7/site-packages/django/core/handlers/base.py", line 172, in _get_response
    resolver_match = resolver.resolve(request.path_info)
  File "/home/ubuntu/artemis/env/local/lib/python2.7/site-packages/django/urls/resolvers.py", line 362, in resolve
    for pattern in self.url_patterns:
  File "/home/ubuntu/artemis/env/local/lib/python2.7/site-packages/django/utils/functional.py", line 35, in __get__
    res = instance.__dict__[self.name] = self.func(instance)
  File "/home/ubuntu/artemis/env/local/lib/python2.7/site-packages/django/urls/resolvers.py", line 405, in url_patterns
    patterns = getattr(self.urlconf_module, "urlpatterns", self.urlconf_module)
  File "/home/ubuntu/artemis/env/local/lib/python2.7/site-packages/django/utils/functional.py", line 35, in __get__
    res = instance.__dict__[self.name] = self.func(instance)
  File "/home/ubuntu/artemis/env/local/lib/python2.7/site-packages/django/urls/resolvers.py", line 398, in urlconf_module
    return import_module(self.urlconf_name)
  File "/usr/lib/python2.7/importlib/__init__.py", line 37, in import_module
    __import__(name)
  File "/home/ubuntu/artemis/artemis/artemis/urls.py", line 21, in <module>
    from base.views import Home
  File "/home/ubuntu/artemis/artemis/artemis/base/views.py", line 7
    return HttpResponse(html)
         ^
SyntaxError: invalid syntax
2017-11-01 21:16:43,581 ERROR django.request Internal Server Error: /home
Traceback (most recent call last):
  File "/home/ubuntu/artemis/env/local/lib/python2.7/site-packages/django/core/handlers/exception.py", line 41, in inner
    response = get_response(request)
  File "/home/ubuntu/artemis/env/local/lib/python2.7/site-packages/django/utils/deprecation.py", line 138, in __call__
    response = self.process_request(request)
  File "/home/ubuntu/artemis/env/local/lib/python2.7/site-packages/django/middleware/common.py", line 62, in process_request
    if self.should_redirect_with_slash(request):
  File "/home/ubuntu/artemis/env/local/lib/python2.7/site-packages/django/middleware/common.py", line 80, in should_redirect_with_slash
    not is_valid_path(request.path_info, urlconf) and
  File "/home/ubuntu/artemis/env/local/lib/python2.7/site-packages/django/urls/base.py", line 158, in is_valid_path
    resolve(path, urlconf)
  File "/home/ubuntu/artemis/env/local/lib/python2.7/site-packages/django/urls/base.py", line 27, in resolve
    return get_resolver(urlconf).resolve(path)
  File "/home/ubuntu/artemis/env/local/lib/python2.7/site-packages/django/urls/resolvers.py", line 362, in resolve
    for pattern in self.url_patterns:
  File "/home/ubuntu/artemis/env/local/lib/python2.7/site-packages/django/utils/functional.py", line 35, in __get__
    res = instance.__dict__[self.name] = self.func(instance)
  File "/home/ubuntu/artemis/env/local/lib/python2.7/site-packages/django/urls/resolvers.py", line 405, in url_patterns
    patterns = getattr(self.urlconf_module, "urlpatterns", self.urlconf_module)
  File "/home/ubuntu/artemis/env/local/lib/python2.7/site-packages/django/utils/functional.py", line 35, in __get__
    res = instance.__dict__[self.name] = self.func(instance)
  File "/home/ubuntu/artemis/env/local/lib/python2.7/site-packages/django/urls/resolvers.py", line 398, in urlconf_module
    return import_module(self.urlconf_name)
  File "/usr/lib/python2.7/importlib/__init__.py", line 37, in import_module
    __import__(name)
  File "/home/ubuntu/artemis/artemis/artemis/urls.py", line 21, in <module>
    from base.views import Home
  File "/home/ubuntu/artemis/artemis/artemis/base/views.py", line 7
    return HttpResponse(html)
         ^
SyntaxError: invalid syntax
2017-11-01 21:17:16,668 ERROR django.request Internal Server Error: /home/
Traceback (most recent call last):
  File "/home/ubuntu/artemis/env/local/lib/python2.7/site-packages/django/core/handlers/exception.py", line 41, in inner
    response = get_response(request)
  File "/home/ubuntu/artemis/env/local/lib/python2.7/site-packages/django/core/handlers/base.py", line 187, in _get_response
    response = self.process_exception_by_middleware(e, request)
  File "/home/ubuntu/artemis/env/local/lib/python2.7/site-packages/django/core/handlers/base.py", line 185, in _get_response
    response = wrapped_callback(request, *callback_args, **callback_kwargs)
TypeError: __init__() takes exactly 1 argument (2 given)
2017-11-01 21:18:24,677 ERROR django.request Internal Server Error: /home/
Traceback (most recent call last):
  File "/home/ubuntu/artemis/env/local/lib/python2.7/site-packages/django/core/handlers/exception.py", line 41, in inner
    response = get_response(request)
  File "/home/ubuntu/artemis/env/local/lib/python2.7/site-packages/django/core/handlers/base.py", line 187, in _get_response
    response = self.process_exception_by_middleware(e, request)
  File "/home/ubuntu/artemis/env/local/lib/python2.7/site-packages/django/core/handlers/base.py", line 185, in _get_response
    response = wrapped_callback(request, *callback_args, **callback_kwargs)
  File "/home/ubuntu/artemis/env/local/lib/python2.7/site-packages/django/views/generic/base.py", line 68, in view
    return self.dispatch(request, *args, **kwargs)
  File "/home/ubuntu/artemis/env/local/lib/python2.7/site-packages/django/views/generic/base.py", line 88, in dispatch
    return handler(request, *args, **kwargs)
  File "/home/ubuntu/artemis/artemis/artemis/base/views.py", line 6, in get
    html = "<html><body>It is now {}.</body></html>".format(datetime.datetime.now())
NameError: global name 'datetime' is not defined
2017-11-01 21:29:19,904 ERROR django.request Internal Server Error: /home/
Traceback (most recent call last):
  File "/home/ubuntu/artemis/env/local/lib/python2.7/site-packages/django/core/handlers/exception.py", line 41, in inner
    response = get_response(request)
  File "/home/ubuntu/artemis/env/local/lib/python2.7/site-packages/django/core/handlers/base.py", line 187, in _get_response
    response = self.process_exception_by_middleware(e, request)
  File "/home/ubuntu/artemis/env/local/lib/python2.7/site-packages/django/core/handlers/base.py", line 185, in _get_response
    response = wrapped_callback(request, *callback_args, **callback_kwargs)
  File "/home/ubuntu/artemis/env/local/lib/python2.7/site-packages/django/views/generic/base.py", line 68, in view
    return self.dispatch(request, *args, **kwargs)
  File "/home/ubuntu/artemis/env/local/lib/python2.7/site-packages/django/views/generic/base.py", line 88, in dispatch
    return handler(request, *args, **kwargs)
  File "/home/ubuntu/artemis/env/local/lib/python2.7/site-packages/django/views/generic/base.py", line 155, in get
    context = self.get_context_data(**kwargs)
  File "/home/ubuntu/artemis/artemis/artemis/base/views.py", line 11, in get_context_data
    context = Super(Home, self).get_context_data(**kwargs)
NameError: global name 'Super' is not defined
2017-11-01 21:29:43,829 ERROR django.request Internal Server Error: /home/
Traceback (most recent call last):
  File "/home/ubuntu/artemis/env/local/lib/python2.7/site-packages/django/core/handlers/exception.py", line 41, in inner
    response = get_response(request)
  File "/home/ubuntu/artemis/env/local/lib/python2.7/site-packages/django/core/handlers/base.py", line 217, in _get_response
    response = self.process_exception_by_middleware(e, request)
  File "/home/ubuntu/artemis/env/local/lib/python2.7/site-packages/django/core/handlers/base.py", line 215, in _get_response
    response = response.render()
  File "/home/ubuntu/artemis/env/local/lib/python2.7/site-packages/django/template/response.py", line 107, in render
    self.content = self.rendered_content
  File "/home/ubuntu/artemis/env/local/lib/python2.7/site-packages/django/template/response.py", line 82, in rendered_content
    template = self.resolve_template(self.template_name)
  File "/home/ubuntu/artemis/env/local/lib/python2.7/site-packages/django/template/response.py", line 64, in resolve_template
    return select_template(template, using=self.using)
  File "/home/ubuntu/artemis/env/local/lib/python2.7/site-packages/django/template/loader.py", line 53, in select_template
    raise TemplateDoesNotExist(', '.join(template_name_list), chain=chain)
TemplateDoesNotExist: home.html
2017-11-01 21:31:49,528 ERROR django.request Internal Server Error: /home/
Traceback (most recent call last):
  File "/home/ubuntu/artemis/env/local/lib/python2.7/site-packages/django/core/handlers/exception.py", line 41, in inner
    response = get_response(request)
  File "/home/ubuntu/artemis/env/local/lib/python2.7/site-packages/django/core/handlers/base.py", line 217, in _get_response
    response = self.process_exception_by_middleware(e, request)
  File "/home/ubuntu/artemis/env/local/lib/python2.7/site-packages/django/core/handlers/base.py", line 215, in _get_response
    response = response.render()
  File "/home/ubuntu/artemis/env/local/lib/python2.7/site-packages/django/template/response.py", line 107, in render
    self.content = self.rendered_content
  File "/home/ubuntu/artemis/env/local/lib/python2.7/site-packages/django/template/response.py", line 82, in rendered_content
    template = self.resolve_template(self.template_name)
  File "/home/ubuntu/artemis/env/local/lib/python2.7/site-packages/django/template/response.py", line 64, in resolve_template
    return select_template(template, using=self.using)
  File "/home/ubuntu/artemis/env/local/lib/python2.7/site-packages/django/template/loader.py", line 53, in select_template
    raise TemplateDoesNotExist(', '.join(template_name_list), chain=chain)
TemplateDoesNotExist: home.html
2017-11-01 21:36:42,564 ERROR django.request Internal Server Error: /home/
Traceback (most recent call last):
  File "/home/ubuntu/artemis/env/local/lib/python2.7/site-packages/django/core/handlers/exception.py", line 41, in inner
    response = get_response(request)
  File "/home/ubuntu/artemis/env/local/lib/python2.7/site-packages/django/core/handlers/base.py", line 217, in _get_response
    response = self.process_exception_by_middleware(e, request)
  File "/home/ubuntu/artemis/env/local/lib/python2.7/site-packages/django/core/handlers/base.py", line 215, in _get_response
    response = response.render()
  File "/home/ubuntu/artemis/env/local/lib/python2.7/site-packages/django/template/response.py", line 107, in render
    self.content = self.rendered_content
  File "/home/ubuntu/artemis/env/local/lib/python2.7/site-packages/django/template/response.py", line 82, in rendered_content
    template = self.resolve_template(self.template_name)
  File "/home/ubuntu/artemis/env/local/lib/python2.7/site-packages/django/template/response.py", line 64, in resolve_template
    return select_template(template, using=self.using)
  File "/home/ubuntu/artemis/env/local/lib/python2.7/site-packages/django/template/loader.py", line 53, in select_template
    raise TemplateDoesNotExist(', '.join(template_name_list), chain=chain)
TemplateDoesNotExist: home.html
2017-11-01 21:38:08,132 ERROR django.request Internal Server Error: /home/
Traceback (most recent call last):
  File "/home/ubuntu/artemis/env/local/lib/python2.7/site-packages/django/core/handlers/exception.py", line 41, in inner
    response = get_response(request)
  File "/home/ubuntu/artemis/env/local/lib/python2.7/site-packages/django/core/handlers/base.py", line 217, in _get_response
    response = self.process_exception_by_middleware(e, request)
  File "/home/ubuntu/artemis/env/local/lib/python2.7/site-packages/django/core/handlers/base.py", line 215, in _get_response
    response = response.render()
  File "/home/ubuntu/artemis/env/local/lib/python2.7/site-packages/django/template/response.py", line 107, in render
    self.content = self.rendered_content
  File "/home/ubuntu/artemis/env/local/lib/python2.7/site-packages/django/template/response.py", line 82, in rendered_content
    template = self.resolve_template(self.template_name)
  File "/home/ubuntu/artemis/env/local/lib/python2.7/site-packages/django/template/response.py", line 64, in resolve_template
    return select_template(template, using=self.using)
  File "/home/ubuntu/artemis/env/local/lib/python2.7/site-packages/django/template/loader.py", line 53, in select_template
    raise TemplateDoesNotExist(', '.join(template_name_list), chain=chain)
TemplateDoesNotExist: home.html
2017-11-01 21:42:51,408 ERROR django.request Internal Server Error: /home/
Traceback (most recent call last):
  File "/home/ubuntu/artemis/env/local/lib/python2.7/site-packages/django/core/handlers/exception.py", line 41, in inner
    response = get_response(request)
  File "/home/ubuntu/artemis/env/local/lib/python2.7/site-packages/django/core/handlers/base.py", line 217, in _get_response
    response = self.process_exception_by_middleware(e, request)
  File "/home/ubuntu/artemis/env/local/lib/python2.7/site-packages/django/core/handlers/base.py", line 215, in _get_response
    response = response.render()
  File "/home/ubuntu/artemis/env/local/lib/python2.7/site-packages/django/template/response.py", line 107, in render
    self.content = self.rendered_content
  File "/home/ubuntu/artemis/env/local/lib/python2.7/site-packages/django/template/response.py", line 82, in rendered_content
    template = self.resolve_template(self.template_name)
  File "/home/ubuntu/artemis/env/local/lib/python2.7/site-packages/django/template/response.py", line 64, in resolve_template
    return select_template(template, using=self.using)
  File "/home/ubuntu/artemis/env/local/lib/python2.7/site-packages/django/template/loader.py", line 53, in select_template
    raise TemplateDoesNotExist(', '.join(template_name_list), chain=chain)
TemplateDoesNotExist: home.html
2017-11-01 21:44:33,989 ERROR django.request Internal Server Error: /home/
Traceback (most recent call last):
  File "/home/ubuntu/artemis/env/local/lib/python2.7/site-packages/django/core/handlers/exception.py", line 41, in inner
    response = get_response(request)
  File "/home/ubuntu/artemis/env/local/lib/python2.7/site-packages/django/core/handlers/base.py", line 217, in _get_response
    response = self.process_exception_by_middleware(e, request)
  File "/home/ubuntu/artemis/env/local/lib/python2.7/site-packages/django/core/handlers/base.py", line 215, in _get_response
    response = response.render()
  File "/home/ubuntu/artemis/env/local/lib/python2.7/site-packages/django/template/response.py", line 107, in render
    self.content = self.rendered_content
  File "/home/ubuntu/artemis/env/local/lib/python2.7/site-packages/django/template/response.py", line 84, in rendered_content
    content = template.render(context, self._request)
  File "/home/ubuntu/artemis/env/local/lib/python2.7/site-packages/django/template/backends/django.py", line 66, in render
    return self.template.render(context)
  File "/home/ubuntu/artemis/env/local/lib/python2.7/site-packages/django/template/base.py", line 207, in render
    return self._render(context)
  File "/home/ubuntu/artemis/env/local/lib/python2.7/site-packages/django/template/base.py", line 199, in _render
    return self.nodelist.render(context)
  File "/home/ubuntu/artemis/env/local/lib/python2.7/site-packages/django/template/base.py", line 990, in render
    bit = node.render_annotated(context)
  File "/home/ubuntu/artemis/env/local/lib/python2.7/site-packages/django/template/base.py", line 957, in render_annotated
    return self.render(context)
  File "/home/ubuntu/artemis/env/local/lib/python2.7/site-packages/django/template/loader_tags.py", line 154, in render
    compiled_parent = self.get_parent(context)
  File "/home/ubuntu/artemis/env/local/lib/python2.7/site-packages/django/template/loader_tags.py", line 151, in get_parent
    return self.find_template(parent, context)
  File "/home/ubuntu/artemis/env/local/lib/python2.7/site-packages/django/template/loader_tags.py", line 131, in find_template
    template_name, skip=history,
  File "/home/ubuntu/artemis/env/local/lib/python2.7/site-packages/django/template/engine.py", line 136, in find_template
    name, template_dirs=dirs, skip=skip,
  File "/home/ubuntu/artemis/env/local/lib/python2.7/site-packages/django/template/loaders/base.py", line 44, in get_template
    contents, origin, origin.template_name, self.engine,
  File "/home/ubuntu/artemis/env/local/lib/python2.7/site-packages/django/template/base.py", line 191, in __init__
    self.nodelist = self.compile_nodelist()
  File "/home/ubuntu/artemis/env/local/lib/python2.7/site-packages/django/template/base.py", line 230, in compile_nodelist
    return parser.parse()
  File "/home/ubuntu/artemis/env/local/lib/python2.7/site-packages/django/template/base.py", line 486, in parse
    raise self.error(token, e)
TemplateSyntaxError: Could not parse the remainder: '('OmniSearchAjax')' from 'url_for('OmniSearchAjax')'
2017-11-01 21:46:12,449 ERROR django.request Internal Server Error: /home/
Traceback (most recent call last):
  File "/home/ubuntu/artemis/env/local/lib/python2.7/site-packages/django/core/handlers/exception.py", line 41, in inner
    response = get_response(request)
  File "/home/ubuntu/artemis/env/local/lib/python2.7/site-packages/django/core/handlers/base.py", line 217, in _get_response
    response = self.process_exception_by_middleware(e, request)
  File "/home/ubuntu/artemis/env/local/lib/python2.7/site-packages/django/core/handlers/base.py", line 215, in _get_response
    response = response.render()
  File "/home/ubuntu/artemis/env/local/lib/python2.7/site-packages/django/template/response.py", line 107, in render
    self.content = self.rendered_content
  File "/home/ubuntu/artemis/env/local/lib/python2.7/site-packages/django/template/response.py", line 84, in rendered_content
    content = template.render(context, self._request)
  File "/home/ubuntu/artemis/env/local/lib/python2.7/site-packages/django/template/backends/django.py", line 66, in render
    return self.template.render(context)
  File "/home/ubuntu/artemis/env/local/lib/python2.7/site-packages/django/template/base.py", line 207, in render
    return self._render(context)
  File "/home/ubuntu/artemis/env/local/lib/python2.7/site-packages/django/template/base.py", line 199, in _render
    return self.nodelist.render(context)
  File "/home/ubuntu/artemis/env/local/lib/python2.7/site-packages/django/template/base.py", line 990, in render
    bit = node.render_annotated(context)
  File "/home/ubuntu/artemis/env/local/lib/python2.7/site-packages/django/template/base.py", line 957, in render_annotated
    return self.render(context)
  File "/home/ubuntu/artemis/env/local/lib/python2.7/site-packages/django/template/loader_tags.py", line 154, in render
    compiled_parent = self.get_parent(context)
  File "/home/ubuntu/artemis/env/local/lib/python2.7/site-packages/django/template/loader_tags.py", line 151, in get_parent
    return self.find_template(parent, context)
  File "/home/ubuntu/artemis/env/local/lib/python2.7/site-packages/django/template/loader_tags.py", line 131, in find_template
    template_name, skip=history,
  File "/home/ubuntu/artemis/env/local/lib/python2.7/site-packages/django/template/engine.py", line 136, in find_template
    name, template_dirs=dirs, skip=skip,
  File "/home/ubuntu/artemis/env/local/lib/python2.7/site-packages/django/template/loaders/base.py", line 44, in get_template
    contents, origin, origin.template_name, self.engine,
  File "/home/ubuntu/artemis/env/local/lib/python2.7/site-packages/django/template/base.py", line 191, in __init__
    self.nodelist = self.compile_nodelist()
  File "/home/ubuntu/artemis/env/local/lib/python2.7/site-packages/django/template/base.py", line 230, in compile_nodelist
    return parser.parse()
  File "/home/ubuntu/artemis/env/local/lib/python2.7/site-packages/django/template/base.py", line 486, in parse
    raise self.error(token, e)
TemplateSyntaxError: Could not parse the remainder: '()' from 'csrf_token()'
2017-11-01 21:48:13,202 WARNING django.request Not Found: /omnisearchajax/
2017-11-01 21:48:14,430 WARNING django.request Not Found: /omnisearchajax/
2017-11-01 21:48:16,967 WARNING django.request Not Found: /omnisearchajax/
